Workbook

Sheet Özet
B1: Proje Özeti
B2: Plan sekmesindeki Durum sütunundan otomatik hesaplanır.
B4: Faz | C4: Toplam | D4: Açık | E4: Devam | F4: Beklemede | G4: Tamamlandı | H4: İlerleme
B5: A · Hazırlık ve Tasarım | C5: =COUNTIFS(Plan!$B$5:$B$76,B5) -> 8 | D5: =COUNTIFS(Plan!$B$5:$B$76,$B5,Plan!$G$5:$G$76,"Açık") -> 3 | E5: =COUNTIFS(Plan!$B$5:$B$76,$B5,Plan!$G$5:$G$76,"Devam") -> 0 | F5: =COUNTIFS(Plan!$B$5:$B$76,$B5,Plan!$G$5:$G$76,"Beklemede") -> 0 | G5: =COUNTIFS(Plan!$B$5:$B$76,$B5,Plan!$G$5:$G$76,"Tamamlandı") -> 5 | H5: =IF(C5=0,0,G5/C5) -> 0.625
B6: B · Ekip Sunumu ve Geri Bildirim | C6: =COUNTIFS(Plan!$B$5:$B$76,B6) -> 7 | D6: =COUNTIFS(Plan!$B$5:$B$76,$B6,Plan!$G$5:$G$76,"Açık") -> 7 | E6: =COUNTIFS(Plan!$B$5:$B$76,$B6,Plan!$G$5:$G$76,"Devam") -> 0 | F6: =COUNTIFS(Plan!$B$5:$B$76,$B6,Plan!$G$5:$G$76,"Beklemede") -> 0 | G6: =COUNTIFS(Plan!$B$5:$B$76,$B6,Plan!$G$5:$G$76,"Tamamlandı") -> 0 | H6: =IF(C6=0,0,G6/C6) -> 0
B7: C · Kurumsal Onay ve Altyapı Kararları | C7: =COUNTIFS(Plan!$B$5:$B$76,B7) -> 7 | D7: =COUNTIFS(Plan!$B$5:$B$76,$B7,Plan!$G$5:$G$76,"Açık") -> 7 | E7: =COUNTIFS(Plan!$B$5:$B$76,$B7,Plan!$G$5:$G$76,"Devam") -> 0 | F7: =COUNTIFS(Plan!$B$5:$B$76,$B7,Plan!$G$5:$G$76,"Beklemede") -> 0 | G7: =COUNTIFS(Plan!$B$5:$B$76,$B7,Plan!$G$5:$G$76,"Tamamlandı") -> 0 | H7: =IF(C7=0,0,G7/C7) -> 0
B8: D · Faz 0 — Veri ve Kural Envanteri | C8: =COUNTIFS(Plan!$B$5:$B$76,B8) -> 12 | D8: =COUNTIFS(Plan!$B$5:$B$76,$B8,Plan!$G$5:$G$76,"Açık") -> 12 | E8: =COUNTIFS(Plan!$B$5:$B$76,$B8,Plan!$G$5:$G$76,"Devam") -> 0 | F8: =COUNTIFS(Plan!$B$5:$B$76,$B8,Plan!$G$5:$G$76,"Beklemede") -> 0 | G8: =COUNTIFS(Plan!$B$5:$B$76,$B8,Plan!$G$5:$G$76,"Tamamlandı") -> 0 | H8: =IF(C8=0,0,G8/C8) -> 0
B9: E · Faz 1 — İlk Sürüm Geliştirme | C9: =COUNTIFS(Plan!$B$5:$B$76,B9) -> 13 | D9: =COUNTIFS(Plan!$B$5:$B$76,$B9,Plan!$G$5:$G$76,"Açık") -> 13 | E9: =COUNTIFS(Plan!$B$5:$B$76,$B9,Plan!$G$5:$G$76,"Devam") -> 0 | F9: =COUNTIFS(Plan!$B$5:$B$76,$B9,Plan!$G$5:$G$76,"Beklemede") -> 0 | G9: =COUNTIFS(Plan!$B$5:$B$76,$B9,Plan!$G$5:$G$76,"Tamamlandı") -> 0 | H9: =IF(C9=0,0,G9/C9) -> 0
B10: F · Pilot ve Yaygınlaştırma | C10: =COUNTIFS(Plan!$B$5:$B$76,B10) -> 7 | D10: =COUNTIFS(Plan!$B$5:$B$76,$B10,Plan!$G$5:$G$76,"Açık") -> 7 | E10: =COUNTIFS(Plan!$B$5:$B$76,$B10,Plan!$G$5:$G$76,"Devam") -> 0 | F10: =COUNTIFS(Plan!$B$5:$B$76,$B10,Plan!$G$5:$G$76,"Beklemede") -> 0 | G10: =COUNTIFS(Plan!$B$5:$B$76,$B10,Plan!$G$5:$G$76,"Tamamlandı") -> 0 | H10: =IF(C10=0,0,G10/C10) -> 0
B11: G · Faz 2 ve Sürekli İyileştirme | C11: =COUNTIFS(Plan!$B$5:$B$76,B11) -> 11 | D11: =COUNTIFS(Plan!$B$5:$B$76,$B11,Plan!$G$5:$G$76,"Açık") -> 11 | E11: =COUNTIFS(Plan!$B$5:$B$76,$B11,Plan!$G$5:$G$76,"Devam") -> 0 | F11: =COUNTIFS(Plan!$B$5:$B$76,$B11,Plan!$G$5:$G$76,"Beklemede") -> 0 | G11: =COUNTIFS(Plan!$B$5:$B$76,$B11,Plan!$G$5:$G$76,"Tamamlandı") -> 0 | H11: =IF(C11=0,0,G11/C11) -> 0
B12: TOPLAM | C12: =SUM(C5:C11) -> 65 | D12: =SUM(D5:D11) -> 60 | E12: =SUM(E5:E11) -> 0 | F12: =SUM(F5:F11) -> 0 | G12: =SUM(G5:G11) -> 5 | H12: =IF(C12=0,0,G12/C12) -> 0.076923077
B14: Gecikmiş görev sayısı (hedef tarihi geçmiş, tamamlanmamış) | C14: =COUNTIFS(Plan!$H$5:$H$76,"<"&TODAY(),Plan!$G$5:$G$76,"<>Tamamlandı") -> 0
B16: Kritik yol — bunlar gecikirse proje durur
B17: • C2 · Barındırma kararı (bulut mu kurum içi mi) — her şeyin ön koşulu
B18: • C3 · AI servisine hangi verinin gidebileceği (KVKK / uyum)
B19: • C4 · Geliştirme kaynağının belirlenmesi
B20: • D2 · Alan sözlüğü (birim, %100/pay, kur) — sayıların doğruluğu buna bağlı
B21: • D6–D8 · Baz prim, yetki matrisi, kural listesi — UW Asistanı bunlarsız çalışmaz
B22: • E12 · Mutabakat testi — tutmazsa yayına çıkılmaz
B24: Paralel yürüyebilecek işler
B25: • D12 · Kütüphane dokümanlarının toplanması — ekip şimdiden başlayabilir
B26: • C5 · Yangın ekibiyle görüşme — sunumdan önce de yapılabilir
B27: • D1 · Veri kaynakları listesi — onay sürecini beklemeden çıkarılabilir

Sheet Plan
A1: Komuta Merkezi — Sorumluluk Masası · Proje Yapılacaklar Listesi
A2: Durum sütunundan seçim yapın (Açık / Devam / Beklemede / Tamamlandı). Sarı hücreler sizin dolduracağınız alanlardır. Özet sekmesi otomatik güncellenir.
A4: No | B4: Faz | C4: Görev | D4: Bitti sayılır / Çıktı | E4: Sorumlu | F4: Bağımlılık | G4: Durum | H4: Hedef tarih | I4: Bitiş tarihi | J4: Not
A5: A · Hazırlık ve Tasarım
A6: A1 | B6: A · Hazırlık ve Tasarım | C6: Yangın dashboard paketini analiz et | D6: Sorumluluk uyarlama analizi (ANALIZ-SORUMLULUK-DASHBOARD.md) | E6: Ben + Claude | F6: — | G6: Tamamlandı
A7: A2 | B7: A · Hazırlık ve Tasarım | C7: Modül yapısını netleştir | D7: Yapı Excel’i: 4 katman, 7 modül, Detay sekmesi | E7: Ben + Claude | F7: A1 | G7: Tamamlandı
A8: A3 | B8: A · Hazırlık ve Tasarım | C8: Açık soruları yanıtla, önerileri kabul/ret et | D8: Teyit sekmesi dolu, Öneriler’de ok / Faz 2 işaretli | E8: Ben | F8: A2 | G8: Tamamlandı
A9: A4 | B9: A · Hazırlık ve Tasarım | C9: Sigortalı 360° kartı (Ö01) için karar ver | D9: Öneriler sekmesinde ‘??’ yerine ok / Faz 2 / ret | E9: Ben | F9: A3 | G9: Açık | J9: Excel’de hâlâ ‘??’ işaretli
A10: A5 | B10: A · Hazırlık ve Tasarım | C10: Ekran görseli promptlarını hazırla | D10: GORSEL-PROMPTLARI.md | E10: Claude | F10: A3 | G10: Tamamlandı
A11: A6 | B11: A · Hazırlık ve Tasarım | C11: ChatGPT’de 10 ekran görselini üret | D11: Görsel-01 … Görsel-10.png kaydedildi | E11: Ben | F11: A5 | G11: Açık | J11: Tek sohbette, önce Stil Kilidi + Ekran 1
A12: A7 | B12: A · Hazırlık ve Tasarım | C12: Görselleri kontrol listesiyle gözden geçir ve revize ettir | D12: Kırmızı kullanımı, rozetler, Türkçe karakter, sıralama yok kontrolü yapıldı | E12: Ben | F12: A6 | G12: Açık | J12: Promptlar dosyası §3
A13: A8 | B13: A · Hazırlık ve Tasarım | C13: Sunum brifingini hazırla | D13: Sunum-Brifingi-Komuta-Merkezi.docx | E13: Claude | F13: A3 | G13: Tamamlandı
A14: B · Ekip Sunumu ve Geri Bildirim
A15: B1 | B15: B · Ekip Sunumu ve Geri Bildirim | C15: Brifingdeki yer tutucuları doldur | D15: [sayı] son haftaya kalan yenileme, [süre] fakültatif belge, [tarih], [çeyrek], [BT teyidi] dolu | E15: Ben | F15: A8 | G15: Açık | J15: Rakam yoksa slayttan çıkar, uydurma
A16: B2 | B16: B · Ekip Sunumu ve Geri Bildirim | C16: Yeni sohbette sunumu hazırlat | D16: 13–15 slaytlık PPTX, görseller yerleşik | E16: Ben + Claude | F16: B1, A7 | G16: Açık | J16: Brifing + görseller birlikte eklenir
A17: B3 | B17: B · Ekip Sunumu ve Geri Bildirim | C17: Geri bildirim formunu hazırla | D17: MS Forms: brifing §9’daki 9 soru + serbest alan | E17: Ben | F17: B2 | G17: Açık
A18: B4 | B18: B · Ekip Sunumu ve Geri Bildirim | C18: Sunumu ekiple yap | D18: Toplantı yapıldı, form linki paylaşıldı | E18: Ben | F18: B2, B3 | G18: Açık | J18: Süre: 20–25 dk + 15–20 dk tartışma
A19: B5 | B19: B · Ekip Sunumu ve Geri Bildirim | C19: Geri bildirimleri topla | D19: Tüm UW’lerden form yanıtı alındı | E19: Ekip | F19: B4 | G19: Açık | J19: Son tarih brifingdeki [tarih]
A20: B6 | B20: B · Ekip Sunumu ve Geri Bildirim | C20: Önerileri sınıfla ve yapı Excel’ine işle | D20: Her öneri: Faz 1 / Faz 2 / Değerlendirilecek / Ret | E20: Ben + Claude | F20: B5 | G20: Açık
A21: B7 | B21: B · Ekip Sunumu ve Geri Bildirim | C21: Sonucu ekiple paylaş | D21: Kısa mail: ne alındı, ne ertelendi, neden | E21: Ben | F21: B6 | G21: Açık | J21: Katılımı sürdürmek için kritik
A22: C · Kurumsal Onay ve Altyapı Kararları
A23: C1 | B23: C · Kurumsal Onay ve Altyapı Kararları | C23: Projeyi üst yönetime / ilgili birime ilet ve onay al | D23: Yazılı onay veya toplantı kararı | E23: Ben | F23: B6 | G23: Açık | J23: Kapsam, fayda, kaynak ihtiyacı tek sayfa
A24: C2 | B24: C · Kurumsal Onay ve Altyapı Kararları | C24: Bilgi güvenliği ve BT ile barındırma kararını ver | D24: Kurum içi mi, bulut mu? Müşteri verisi nerede duracak? Karar yazılı | E24: Ben + BT | F24: C1 | G24: Açık | J24: Yangın paneli dış bulutta (Vercel/Supabase) — aynısı kabul edilir mi teyit
A25: C3 | B25: C · Kurumsal Onay ve Altyapı Kararları | C25: Yapay zekâ servisine veri gönderimini netleştir | D25: KVKK ve kurum politikası açısından hangi veri modele gidebilir, maskeleme kuralı | E25: Ben + BT + Hukuk/Uyum | F25: C2 | G25: Açık | J25: Sigortalı adı, TCKN/VKN gönderilmemesi varsayılan olmalı
A26: C4 | B26: C · Kurumsal Onay ve Altyapı Kararları | C26: Geliştirme kaynağını belirle | D26: Yazılımcı / iç BT / Yangın ekibinin geliştiricisi / Claude ile kendin — karar | E26: Ben | F26: C1 | G26: Açık
A27: C5 | B27: C · Kurumsal Onay ve Altyapı Kararları | C27: Yangın ekibiyle görüş | D27: Ortak altyapı, kod paylaşımı, yaşadıkları sorunlar konuşuldu | E27: Ben | F27: C4 | G27: Açık | J27: Paketteki 10 ölçüm kuralı ve tek parola sorunu
A28: C6 | B28: C · Kurumsal Onay ve Altyapı Kararları | C28: AI kullanım bütçesi ve kotası | D28: Kullanıcı × kullanım tahmini, aylık tavan onaylı | E28: Ben + BT | F28: C4 | G28: Açık | J28: Yorum butonu isteğe bağlı olmalı, otomatik değil
A29: C7 | B29: C · Kurumsal Onay ve Altyapı Kararları | C29: Kullanıcı listesi ve erişim kapsamı | D29: Her UW → sorumlu olduğu bölgeler; yönetici tümü | E29: Ben | F29: C1 | G29: Açık | J29: Teyit T08 cevabı
A30: D · Faz 0 — Veri ve Kural Envanteri
A31: D1 | B31: D · Faz 0 — Veri ve Kural Envanteri | C31: Veri kaynakları listesini çıkar | D31: Üretim, teklif, poliçe, yenileme, hasar, acente/KIO, bütçe, TSB — her biri için sistem ve dosya adı | E31: Ben + BT | F31: C2 | G31: Açık
A32: D2 | B32: D · Faz 0 — Veri ve Kural Envanteri | C32: Alan sözlüğünü hazırla | D32: Her kolon: anlamı, birimi (% / kesir / ‰), %100 mü pay mı, döviz kuru kuralı, sahibi | E32: Ben + Yazılımcı | F32: D1 | G32: Açık | J32: En çok hata buradan çıkar
A33: D3 | B33: D · Faz 0 — Veri ve Kural Envanteri | C33: Veri kalitesi kurallarını onayla | D33: BÖLGE boş → KSM · Acente boş → aynı Akış No · Poliçe No 0 → pipeline | E33: Ben | F33: D2 | G33: Açık | J33: Çeyrek rapor metodolojisiyle aynı
A34: D4 | B34: D · Faz 0 — Veri ve Kural Envanteri | C34: Örnek veri setlerini hazırla | D34: Anonimleştirilmiş extract’lar yazılımcıya teslim | E34: Ben + BT | F34: D2, C3, C4 | G34: Açık
A35: D5 | B35: D · Faz 0 — Veri ve Kural Envanteri | C35: Hasar verisinde UW yılı kırılımını teyit et | D35: UW yılı / kaza yılı alanı var mı — evet/hayır | E35: Ben + Hasar birimi | F35: D1 | G35: Açık | J35: Yoksa hasar panosu ertelenir
A36: D6 | B36: D · Faz 0 — Veri ve Kural Envanteri | C36: Her risk için baz prim ve fiyat kurallarını tanımla | D36: Ürün bazında baz prim tablosu ve fiyat kuralları dokümanı | E36: Ben + Ekip | F36: D2 | G36: Açık | J36: Teyit T01 cevabı
A37: D7 | B37: D · Faz 0 — Veri ve Kural Envanteri | C37: Yetki matrisini dokümante et | D37: UW bazında ürün / limit / prim yetkileri tablosu | E37: Ben | F37: C7 | G37: Açık | J37: Yetki aşımı uyarısının kaynağı
A38: D8 | B38: D · Faz 0 — Veri ve Kural Envanteri | C38: Kural tabanlı uyarı listesini yaz | D38: Yetki, yaptırım, ABD/Kanada, treaty istisnası, retro kesinti — tetik koşulu ve mesajı | E38: Ben | F38: D7, D9 | G38: Açık | J38: Teyit T04: kural tabanlı
A39: D9 | B39: D · Faz 0 — Veri ve Kural Envanteri | C39: Treaty limit ve istisna listesini al | D39: Ürün bazında treaty limiti, istisnalar, fakültatif eşiği | E39: Ben + Reasürans | F39: D1 | G39: Açık
A40: D10 | B40: D · Faz 0 — Veri ve Kural Envanteri | C40: Eşikleri sabitle (ayar dosyası) | D40: 100.000 ₺ · 60/30/15 gün · SLA 7 gün · HHI 1.500/2.500 · değerlendirme kriterleri | E40: Ben | F40: D3 | G40: Açık | J40: Koda gömülmez, ayar dosyasına yazılır
A41: D11 | B41: D · Faz 0 — Veri ve Kural Envanteri | C41: Ürün bazlı risk bilgi formlarını tasarla | D41: 438, 437, 450, 415, 470, 474 için zorunlu alanlar | E41: Ben + Ekip | F41: B6 | G41: Açık | J41: Geri bildirim sorusu 4’ten beslenir
...
